<?xml version="1.0"?>
<robot name="kr20">
  <!-- World frame -->
  <link name="world"/>

  <!-- Arm fixed to world frame -->
  <joint name="world__link_00" type="fixed">
    <parent link="world"/>
    <child link="link_00"/>
    <origin rpy="0 0 0" xyz="0 0 0"/>
  </joint>

  <!-- Material definitions -->
  <material name="Orange">
    <color rgba="0.95 0.5 0.15 1.0"/>
  </material>

  <material name="Grey">
    <color rgba="0.7 0.7 0.7 1.0"/>
  </material>

  <material name="Black">
    <color rgba="0.0 0.0 0.0 1.0"/>
  </material>

  <!-- Link 00 -->
  <link name="link_00">
    <visual>
      <origin rpy="0 0 0" xyz="-0.5 0 0.65"/>
      <geometry>
        <box size="0.3 0.3 1.3"/>
      </geometry>
      <material name="Black"/>
    </visual>
    <collision>
      <origin rpy="0 0 0" xyz="-0.5 0 0.65"/>
      <geometry>
        <box size="0.3 0.3 1.3"/>
      </geometry>
    </collision>
    <inertial>
      <mass value="157.633"/>
      <inertia ixx="1" ixy="0" ixz="0" iyy="1" iyz="0" izz="1"/>
    </inertial>
  </link>

  <!-- Joint between link_00 and link_12 -->
  <joint name="link_00__link_12" type="revolute">
    <axis xyz="0 0 1"/>
    <origin rpy="0 0 0" xyz="0 0 0.15"/>
    <parent link="link_00"/>
    <child link="link_12"/>
    <limit effort="1000" lower="-3.14" upper="3.14" velocity="0.5"/>
  </joint>

  <!-- Link 12 -->
  <link name="link_12">
    <visual>
      <origin rpy="0 0 0" xyz="-0.05 0 0"/>
      <geometry>
        <box size="0.6 0.3 0.3"/>
      </geometry>
      <material name="Orange"/>
    </visual>
    <collision>
      <origin rpy="0 0 0" xyz="-0.05 0 0"/>
      <geometry>
        <box size="0.6 0.3 0.3"/>
      </geometry>
    </collision>
    <inertial>
      <mass value="157.633"/>
      <inertia ixx="1" ixy="0" ixz="0" iyy="1" iyz="0" izz="1"/>
    </inertial>
  </link>

  <!-- Joint between link_12 and link_01 -->
  <joint name="link_12__link_01" type="revolute">
    <axis xyz="0 0 1"/>
    <origin rpy="0 0 0" xyz="0 0 0.15"/>
    <parent link="link_12"/>
    <child link="link_01"/>
    <limit effort="1000" lower="-2" upper="2" velocity="0.5"/>
  </joint>

  <!-- Link 01 -->
  <link name="link_01">
    <visual>
      <origin rpy="0 0 0" xyz="0 0 0"/>
      <geometry>
        <mesh filename="package://kuka_kr20_description/meshes/link01.stl" scale="0.001 0.001 0.001"/>
      </geometry>
      <material name="Orange"/>
    </visual>
    <collision>
      <origin rpy="0 0 0" xyz="0 0 0"/>
      <geometry>
        <mesh filename="package://kuka_kr20_description/meshes/link01.stl" scale="0.001 0.001 0.001"/>
      </geometry>
    </collision>
    <inertial>
      <mass value="157.633"/>
      <inertia ixx="13.235" ixy="0" ixz="0" iyy="13.235" iyz="0" izz="9.655"/>
    </inertial>
  </link>

  <!-- Joint between link_01 and link_02 -->
  <joint name="link_01__link_02" type="revolute">
    <axis xyz="0 1 0"/>
    <origin rpy="0 0 0" xyz="0.160 -0.095 0.220"/>
    <parent link="link_01"/>
    <child link="link_02"/>
    <limit effort="1000" lower="-1.5708" upper="1.7453" velocity="0.5"/>
  </joint>

  <!-- Link 02 -->
  <link name="link_02">
    <visual>
      <origin rpy="0 0 0" xyz="0 0 0"/>
      <geometry>
        <mesh filename="package://kuka_kr20_description/meshes/link02.stl" scale="0.001 0.001 0.001"/>
      </geometry>
      <material name="Orange"/>
    </visual>
    <collision>
      <origin rpy="0 0 0" xyz="0 0 0"/>
      <geometry>
        <mesh filename="package://kuka_kr20_description/meshes/link02.stl" scale="0.001 0.001 0.001"/>
      </geometry>
    </collision>
    <inertial>
      <mass value="10"/>
      <inertia ixx="10" ixy="0" ixz="0" iyy="10" iyz="0" izz="10"/>
    </inertial>
  </link>

  <!-- Joint between link_02 and link_03 -->
  <joint name="link_02__link_03" type="revolute">
    <axis xyz="0 -1 0"/>
    <origin rpy="0 0 0" xyz="0.00 -0.01 0.780"/>
    <parent link="link_02"/>
    <child link="link_03"/>
    <limit effort="1000" lower="-1.55" upper="2" velocity="0.5"/>
  </joint>

  <!-- Link 03 -->
  <link name="link_03">
    <visual>
      <origin rpy="0 0 0" xyz="0 0 0"/>
      <geometry>
        <mesh filename="package://kuka_kr20_description/meshes/link03.stl" scale="0.001 0.001 0.001"/>
      </geometry>
      <material name="Orange"/>
    </visual>
    <collision>
      <origin rpy="0 0 0" xyz="0 0 0"/>
      <geometry>
        <mesh filename="package://kuka_kr20_description/meshes/link03.stl" scale="0.001 0.001 0.001"/>
      </geometry>
    </collision>
    <inertial>
      <mass value="7"/>
      <inertia ixx="5" ixy="0" ixz="0" iyy="5" iyz="0" izz="5"/>
    </inertial>
  </link>

  <!-- Joint between link_03 and link_04 -->
  <joint name="link_03__link_04" type="revolute">
    <axis xyz="1 0 0"/>
    <origin rpy="0 0 0" xyz="0.700 0.105 0.150"/>
    <parent link="link_03"/>
    <child link="link_04"/>
    <limit effort="1000" lower="-3.0" upper="3.0" velocity="0.5"/>
  </joint>

  <!-- Link 04 -->
  <link name="link_04">
    <visual>
      <origin rpy="0 0 0" xyz="0 0 0"/>
      <geometry>
        <mesh filename="package://kuka_kr20_description/meshes/link04.stl" scale="0.001 0.001 0.001"/>
      </geometry>
      <material name="Orange"/>
    </visual>
    <collision>
      <origin rpy="0 0 0" xyz="0 0 0"/>
      <geometry>
        <mesh filename="package://kuka_kr20_description/meshes/link04.stl" scale="0.001 0.001 0.001"/>
      </geometry>
    </collision>
    <inertial>
      <mass value="2"/>
      <inertia ixx="1" ixy="0" ixz="0" iyy="1" iyz="0" izz="1"/>
    </inertial>
  </link>

  <!-- Joint between link_04 and link_05 -->
  <joint name="link_04__link_05" type="revolute">
    <axis xyz="0 -1 0"/>
    <origin rpy="0 0 0" xyz="0.155 0.000 0.000"/>
    <parent link="link_04"/>
    <child link="link_05"/>
    <limit effort="1000" lower="-2.0" upper="2.0" velocity="0.5"/>
  </joint>

  <!-- Link 05 -->
  <link name="link_05">
    <visual>
      <origin rpy="0 0 0" xyz="0 0 0"/>
      <geometry>
        <mesh filename="package://kuka_kr20_description/meshes/link05.stl" scale="0.001 0.001 0.001"/>
      </geometry>
      <material name="Orange"/>
    </visual>
    <collision>
      <origin rpy="0 0 0" xyz="0 0 0"/>
      <geometry>
        <mesh filename="package://kuka_kr20_description/meshes/link05.stl" scale="0.001 0.001 0.001"/>
      </geometry>
    </collision>
    <inertial>
      <mass value="2"/>
      <inertia ixx="1" ixy="0" ixz="0" iyy="1" iyz="0" izz="1"/>
    </inertial>
  </link>

  <!-- Shovel Gripper Components -->

  <!-- Shovel Base -->
  <link name="shovel_base">
    <visual>
      <origin xyz="0 0 0" rpy="0 0 0"/>
      <geometry>
        <cylinder radius="0.05" length="0.1"/>
      </geometry>
      <material name="Grey"/>
    </visual>
    <collision>
      <origin xyz="0 0 0" rpy="0 0 0"/>
      <geometry>
        <cylinder radius="0.05" length="0.1"/>
      </geometry>
    </collision>
    <inertial>
      <mass value="0.5"/>
      <inertia ixx="0.01" ixy="0" ixz="0" iyy="0.01" iyz="0" izz="0.01"/>
    </inertial>
  </link>

  <!-- Joint between link_05 and shovel_base -->
  <joint name="link05__shovel_base" type="revolute">
    <axis xyz="0 1 0"/>
    <parent link="link_05"/>
    <child link="shovel_base"/>
    <origin xyz="0.115 0 0" rpy="0 0 0"/>
    <limit effort="1000" lower="-3.14" upper="3.14" velocity="0.5"/>
  </joint>

  <!-- Shovel Plate -->
  <link name="shovel_plate">
    <visual>
      <origin xyz="0.15 0 0" rpy="0 0.2 0"/>
      <geometry>
        <box size="0.3 0.2 0.02"/>
      </geometry>
      <material name="Grey"/>
    </visual>
    <collision>
      <origin xyz="0.15 0 0" rpy="0 0.2 0"/>
      <geometry>
        <box size="0.3 0.2 0.02"/>
      </geometry>
    </collision>
    <inertial>
      <mass value="0.2"/>
      <inertia ixx="0.01" ixy="0" ixz="0" iyy="0.01" iyz="0" izz="0.01"/>
    </inertial>
  </link>

  <!-- Fixed joint between shovel_base and shovel_plate -->
  <joint name="shovel_base__shovel_plate" type="fixed">
    <parent link="shovel_base"/>
    <child link="shovel_plate"/>
    <origin xyz="0 0 0" rpy="0 0 0"/>
  </joint>

  <!-- Pusher -->
  <link name="pusher">
    <visual>
      <origin xyz="-0.1 0 0.05" rpy="0 0 0"/>
      <geometry>
        <box size="0.02 0.18 0.1"/>
      </geometry>
      <material name="Black"/>
    </visual>
    <collision>
      <origin xyz="0 0 0.05" rpy="0 0 0"/>
      <geometry>
        <box size="0.02 0.18 0.1"/>
      </geometry>
    </collision>
    <inertial>
      <mass value="0.1"/>
      <inertia ixx="0.01" ixy="0" ixz="0" iyy="0.01" iyz="0" izz="0.01"/>
    </inertial>
  </link>

  <!-- Prismatic joint for pusher -->
  <joint name="shovel_base__pusher" type="prismatic">
    <axis xyz="1 0 0"/>
    <parent link="shovel_base"/>
    <child link="pusher"/>
    <origin xyz="0.15 0 0" rpy="0 0 0"/>
    <limit effort="1000" lower="0" upper="0.25" velocity="0.5"/>
  </joint>
</robot>
